{"$message_type":"diagnostic","message":"mismatched types","code":{"code":"E0308","explanation":"Expected type did not match the received type.\n\nErroneous code examples:\n\n```compile_fail,E0308\nfn plus_one(x: i32) -> i32 {\n    x + 1\n}\n\nplus_one(\"Not a number\");\n//       ^^^^^^^^^^^^^^ expected `i32`, found `&str`\n\nif \"Not a bool\" {\n// ^^^^^^^^^^^^ expected `bool`, found `&str`\n}\n\nlet x: f32 = \"Not a float\";\n//     ---   ^^^^^^^^^^^^^ expected `f32`, found `&str`\n//     |\n//     expected due to this\n```\n\nThis error occurs when an expression was used in a place where the compiler\nexpected an expression of a different type. It can occur in several cases, the\nmost common being when calling a function and passing an argument which has a\ndifferent type than the matching type in the function declaration.\n"},"level":"error","spans":[{"file_name":"src/lib.rs","byte_start":478,"byte_end":650,"line_start":25,"line_end":28,"column_start":9,"column_end":11,"is_primary":true,"text":[{"text":"        pyo3_asyncio::tokio::future_into_py(py, async move {","highlight_start":9,"highlight_end":61},{"text":"            // Your async implementation here","highlight_start":1,"highlight_end":46},{"text":"            Ok(Python::with_gil(|py| func.call0(py).unwrap()))","highlight_start":1,"highlight_end":63},{"text":"        })","highlight_start":1,"highlight_end":11}],"label":"expected `Result<Py<PyAny>, PyErr>`, found `Result<&PyAny, PyErr>`","suggested_replacement":null,"suggestion_applicability":null,"expansion":null},{"file_name":"src/lib.rs","byte_start":449,"byte_end":467,"line_start":24,"line_end":24,"column_start":60,"column_end":78,"is_primary":false,"text":[{"text":"    fn run_async(&self, py: Python<'_>, func: PyObject) -> PyResult<PyObject> {","highlight_start":60,"highlight_end":78}],"label":"expected `Result<Py<PyAny>, PyErr>` because of return type","suggested_replacement":null,"suggestion_applicability":null,"expansion":null}],"children":[{"message":"expected enum `Result<Py<PyAny>, _>`\n   found enum `Result<&PyAny, _>`","code":null,"level":"note","spans":[],"children":[],"rendered":null}],"rendered":"\u001b[0m\u001b[1m\u001b[38;5;9merror[E0308]\u001b[0m\u001b[0m\u001b[1m: mismatched types\u001b[0m\n\u001b[0m  \u001b[0m\u001b[0m\u001b[1m\u001b[38;5;12m--> \u001b[0m\u001b[0msrc/lib.rs:25:9\u001b[0m\n\u001b[0m   \u001b[0m\u001b[0m\u001b[1m\u001b[38;5;12m|\u001b[0m\n\u001b[0m\u001b[1m\u001b[38;5;12m24\u001b[0m\u001b[0m \u001b[0m\u001b[0m\u001b[1m\u001b[38;5;12m|\u001b[0m\u001b[0m   \u001b[0m\u001b[0m    fn run_async(&self, py: Python<'_>, func: PyObject) -> PyResult<PyObject> {\u001b[0m\n\u001b[0m   \u001b[0m\u001b[0m\u001b[1m\u001b[38;5;12m|\u001b[0m\u001b[0m                                                              \u001b[0m\u001b[0m\u001b[1m\u001b[38;5;12m------------------\u001b[0m\u001b[0m \u001b[0m\u001b[0m\u001b[1m\u001b[38;5;12mexpected `Result<Py<PyAny>, PyErr>` because of return type\u001b[0m\n\u001b[0m\u001b[1m\u001b[38;5;12m25\u001b[0m\u001b[0m \u001b[0m\u001b[0m\u001b[1m\u001b[38;5;12m|\u001b[0m\u001b[0m \u001b[0m\u001b[0m\u001b[1m\u001b[38;5;9m/\u001b[0m\u001b[0m \u001b[0m\u001b[0m        pyo3_asyncio::tokio::future_into_py(py, async move {\u001b[0m\n\u001b[0m\u001b[1m\u001b[38;5;12m26\u001b[0m\u001b[0m \u001b[0m\u001b[0m\u001b[1m\u001b[38;5;12m|\u001b[0m\u001b[0m \u001b[0m\u001b[0m\u001b[1m\u001b[38;5;9m|\u001b[0m\u001b[0m \u001b[0m\u001b[0m            // Your async implementation here\u001b[0m\n\u001b[0m\u001b[1m\u001b[38;5;12m27\u001b[0m\u001b[0m \u001b[0m\u001b[0m\u001b[1m\u001b[38;5;12m|\u001b[0m\u001b[0m \u001b[0m\u001b[0m\u001b[1m\u001b[38;5;9m|\u001b[0m\u001b[0m \u001b[0m\u001b[0m            Ok(Python::with_gil(|py| func.call0(py).unwrap()))\u001b[0m\n\u001b[0m\u001b[1m\u001b[38;5;12m28\u001b[0m\u001b[0m \u001b[0m\u001b[0m\u001b[1m\u001b[38;5;12m|\u001b[0m\u001b[0m \u001b[0m\u001b[0m\u001b[1m\u001b[38;5;9m|\u001b[0m\u001b[0m \u001b[0m\u001b[0m        })\u001b[0m\n\u001b[0m   \u001b[0m\u001b[0m\u001b[1m\u001b[38;5;12m|\u001b[0m\u001b[0m \u001b[0m\u001b[0m\u001b[1m\u001b[38;5;9m|__________^\u001b[0m\u001b[0m \u001b[0m\u001b[0m\u001b[1m\u001b[38;5;9mexpected `Result<Py<PyAny>, PyErr>`, found `Result<&PyAny, PyErr>`\u001b[0m\n\u001b[0m   \u001b[0m\u001b[0m\u001b[1m\u001b[38;5;12m|\u001b[0m\n\u001b[0m   \u001b[0m\u001b[0m\u001b[1m\u001b[38;5;12m= \u001b[0m\u001b[0m\u001b[1mnote\u001b[0m\u001b[0m: expected enum `Result<\u001b[0m\u001b[0m\u001b[1m\u001b[35mPy<\u001b[0m\u001b[0mPyAny\u001b[0m\u001b[0m\u001b[1m\u001b[35m>\u001b[0m\u001b[0m, _>`\u001b[0m\n\u001b[0m              found enum `Result<\u001b[0m\u001b[0m\u001b[1m\u001b[35m&\u001b[0m\u001b[0mPyAny, _>`\u001b[0m\n\n"}
{"$message_type":"diagnostic","message":"aborting due to 1 previous error","code":null,"level":"error","spans":[],"children":[],"rendered":"\u001b[0m\u001b[1m\u001b[38;5;9merror\u001b[0m\u001b[0m\u001b[1m: aborting due to 1 previous error\u001b[0m\n\n"}
{"$message_type":"diagnostic","message":"For more information about this error, try `rustc --explain E0308`.","code":null,"level":"failure-note","spans":[],"children":[],"rendered":"\u001b[0m\u001b[1mFor more information about this error, try `rustc --explain E0308`.\u001b[0m\n"}
